[2023-12-03T10:56:14.025+0700] {taskinstance.py:1159} INFO - Dependencies all met for dep_context=non-requeueable deps ti=<TaskInstance: my_first_dag.crawl_data scheduled__2023-12-03T03:16:07.288425+00:00 [queued]>
[2023-12-03T10:56:14.033+0700] {taskinstance.py:1159} INFO - Dependencies all met for dep_context=requeueable deps ti=<TaskInstance: my_first_dag.crawl_data scheduled__2023-12-03T03:16:07.288425+00:00 [queued]>
[2023-12-03T10:56:14.034+0700] {taskinstance.py:1361} INFO - Starting attempt 3 of 3
[2023-12-03T10:56:14.045+0700] {taskinstance.py:1382} INFO - Executing <Task(BashOperator): crawl_data> on 2023-12-03 03:16:07.288425+00:00
[2023-12-03T10:56:14.048+0700] {standard_task_runner.py:57} INFO - Started process 96639 to run task
[2023-12-03T10:56:14.052+0700] {standard_task_runner.py:84} INFO - Running: ['airflow', 'tasks', 'run', 'my_first_dag', 'crawl_data', 'scheduled__2023-12-03T03:16:07.288425+00:00', '--job-id', '25', '--raw', '--subdir', 'DAGS_FOLDER/test_dag.py', '--cfg-path', '/tmp/tmphzxalpsf']
[2023-12-03T10:56:14.053+0700] {standard_task_runner.py:85} INFO - Job 25: Subtask crawl_data
[2023-12-03T10:56:14.073+0700] {task_command.py:416} INFO - Running <TaskInstance: my_first_dag.crawl_data scheduled__2023-12-03T03:16:07.288425+00:00 [running]> on host phuc-ASUS
[2023-12-03T10:56:14.102+0700] {taskinstance.py:1662} INFO - Exporting env vars: AIRFLOW_CTX_DAG_OWNER='airflow' AIRFLOW_CTX_DAG_ID='my_first_dag' AIRFLOW_CTX_TASK_ID='crawl_data' AIRFLOW_CTX_EXECUTION_DATE='2023-12-03T03:16:07.288425+00:00' AIRFLOW_CTX_TRY_NUMBER='3' AIRFLOW_CTX_DAG_RUN_ID='scheduled__2023-12-03T03:16:07.288425+00:00'
[2023-12-03T10:56:14.102+0700] {subprocess.py:63} INFO - Tmp dir root location: /tmp
[2023-12-03T10:56:14.102+0700] {subprocess.py:75} INFO - Running command: ['/usr/bin/bash', '-c', 'cd /home/phuc/Practice/DataScience/DSProject/job_airflow/dags && scrapy crawl quotes']
[2023-12-03T10:56:14.106+0700] {subprocess.py:86} INFO - Output:
[2023-12-03T10:56:14.429+0700] {subprocess.py:93} INFO - 2023-12-03 10:56:14 [scrapy.utils.log] INFO: Scrapy 2.11.0 started (bot: job_cralwer)
[2023-12-03T10:56:14.430+0700] {subprocess.py:93} INFO - 2023-12-03 10:56:14 [scrapy.utils.log] INFO: Versions: lxml 4.9.3.0, libxml2 2.10.3, cssselect 1.2.0, parsel 1.8.1, w3lib 2.1.2, Twisted 22.10.0, Python 3.10.12 (main, Nov 20 2023, 15:14:05) [GCC 11.4.0], pyOpenSSL 23.3.0 (OpenSSL 3.1.4 24 Oct 2023), cryptography 41.0.5, Platform Linux-6.2.0-37-generic-x86_64-with-glibc2.35
[2023-12-03T10:56:14.430+0700] {subprocess.py:93} INFO - Traceback (most recent call last):
[2023-12-03T10:56:14.430+0700] {subprocess.py:93} INFO -   File "/home/phuc/Practice/DataScience/DSProject/venv/lib/python3.10/site-packages/scrapy/spiderloader.py", line 87, in load
[2023-12-03T10:56:14.430+0700] {subprocess.py:93} INFO -     return self._spiders[spider_name]
[2023-12-03T10:56:14.430+0700] {subprocess.py:93} INFO - KeyError: 'quotes'
[2023-12-03T10:56:14.430+0700] {subprocess.py:93} INFO - 
[2023-12-03T10:56:14.430+0700] {subprocess.py:93} INFO - During handling of the above exception, another exception occurred:
[2023-12-03T10:56:14.430+0700] {subprocess.py:93} INFO - 
[2023-12-03T10:56:14.430+0700] {subprocess.py:93} INFO - Traceback (most recent call last):
[2023-12-03T10:56:14.430+0700] {subprocess.py:93} INFO -   File "/home/phuc/Practice/DataScience/DSProject/venv/bin/scrapy", line 8, in <module>
[2023-12-03T10:56:14.430+0700] {subprocess.py:93} INFO -     sys.exit(execute())
[2023-12-03T10:56:14.430+0700] {subprocess.py:93} INFO -   File "/home/phuc/Practice/DataScience/DSProject/venv/lib/python3.10/site-packages/scrapy/cmdline.py", line 161, in execute
[2023-12-03T10:56:14.430+0700] {subprocess.py:93} INFO -     _run_print_help(parser, _run_command, cmd, args, opts)
[2023-12-03T10:56:14.430+0700] {subprocess.py:93} INFO -   File "/home/phuc/Practice/DataScience/DSProject/venv/lib/python3.10/site-packages/scrapy/cmdline.py", line 114, in _run_print_help
[2023-12-03T10:56:14.430+0700] {subprocess.py:93} INFO -     func(*a, **kw)
[2023-12-03T10:56:14.430+0700] {subprocess.py:93} INFO -   File "/home/phuc/Practice/DataScience/DSProject/venv/lib/python3.10/site-packages/scrapy/cmdline.py", line 169, in _run_command
[2023-12-03T10:56:14.430+0700] {subprocess.py:93} INFO -     cmd.run(args, opts)
[2023-12-03T10:56:14.430+0700] {subprocess.py:93} INFO -   File "/home/phuc/Practice/DataScience/DSProject/venv/lib/python3.10/site-packages/scrapy/commands/crawl.py", line 23, in run
[2023-12-03T10:56:14.430+0700] {subprocess.py:93} INFO -     crawl_defer = self.crawler_process.crawl(spname, **opts.spargs)
[2023-12-03T10:56:14.430+0700] {subprocess.py:93} INFO -   File "/home/phuc/Practice/DataScience/DSProject/venv/lib/python3.10/site-packages/scrapy/crawler.py", line 264, in crawl
[2023-12-03T10:56:14.430+0700] {subprocess.py:93} INFO -     crawler = self.create_crawler(crawler_or_spidercls)
[2023-12-03T10:56:14.430+0700] {subprocess.py:93} INFO -   File "/home/phuc/Practice/DataScience/DSProject/venv/lib/python3.10/site-packages/scrapy/crawler.py", line 300, in create_crawler
[2023-12-03T10:56:14.430+0700] {subprocess.py:93} INFO -     return self._create_crawler(crawler_or_spidercls)
[2023-12-03T10:56:14.430+0700] {subprocess.py:93} INFO -   File "/home/phuc/Practice/DataScience/DSProject/venv/lib/python3.10/site-packages/scrapy/crawler.py", line 385, in _create_crawler
[2023-12-03T10:56:14.430+0700] {subprocess.py:93} INFO -     spidercls = self.spider_loader.load(spidercls)
[2023-12-03T10:56:14.430+0700] {subprocess.py:93} INFO -   File "/home/phuc/Practice/DataScience/DSProject/venv/lib/python3.10/site-packages/scrapy/spiderloader.py", line 89, in load
[2023-12-03T10:56:14.431+0700] {subprocess.py:93} INFO -     raise KeyError(f"Spider not found: {spider_name}")
[2023-12-03T10:56:14.431+0700] {subprocess.py:93} INFO - KeyError: 'Spider not found: quotes'
[2023-12-03T10:56:14.518+0700] {subprocess.py:97} INFO - Command exited with return code 1
[2023-12-03T10:56:14.523+0700] {taskinstance.py:1937} ERROR - Task failed with exception
Traceback (most recent call last):
  File "/home/phuc/Practice/DataScience/DSProject/venv/lib/python3.10/site-packages/airflow/operators/bash.py", line 210, in execute
    raise AirflowException(
airflow.exceptions.AirflowException: Bash command failed. The command returned a non-zero exit code 1.
[2023-12-03T10:56:14.525+0700] {taskinstance.py:1400} INFO - Marking task as FAILED. dag_id=my_first_dag, task_id=crawl_data, execution_date=20231203T031607, start_date=20231203T035614, end_date=20231203T035614
[2023-12-03T10:56:14.531+0700] {standard_task_runner.py:104} ERROR - Failed to execute job 25 for task crawl_data (Bash command failed. The command returned a non-zero exit code 1.; 96639)
[2023-12-03T10:56:14.543+0700] {local_task_job_runner.py:228} INFO - Task exited with return code 1
[2023-12-03T10:56:14.555+0700] {taskinstance.py:2778} INFO - 0 downstream tasks scheduled from follow-on schedule check
