[2023-12-17 08:36:30 +0700] [324559] [INFO] Starting gunicorn 21.2.0
[2023-12-17 08:36:30 +0700] [324559] [INFO] Listening at: http://[::]:8793 (324559)
[2023-12-17 08:36:30 +0700] [324559] [INFO] Using worker: sync
[2023-12-17 08:36:30 +0700] [324560] [INFO] Booting worker with pid: 324560
[2023-12-17 08:36:30 +0700] [324562] [INFO] Booting worker with pid: 324562
Traceback (most recent call last):
  File "/home/phuc/Practice/DataScience/DSProject/venv/bin/airflow", line 8, in <module>
    sys.exit(main())
  File "/home/phuc/Practice/DataScience/DSProject/venv/lib/python3.10/site-packages/airflow/__main__.py", line 57, in main
    args.func(args)
  File "/home/phuc/Practice/DataScience/DSProject/venv/lib/python3.10/site-packages/airflow/cli/cli_config.py", line 49, in command
    return func(*args, **kwargs)
  File "/home/phuc/Practice/DataScience/DSProject/venv/lib/python3.10/site-packages/airflow/utils/cli.py", line 114, in wrapper
    return f(*args, **kwargs)
  File "/home/phuc/Practice/DataScience/DSProject/venv/lib/python3.10/site-packages/airflow/cli/commands/task_command.py", line 407, in task_run
    _dag = get_dag(args.subdir, args.dag_id, args.read_from_db)
  File "/home/phuc/Practice/DataScience/DSProject/venv/lib/python3.10/site-packages/airflow/utils/cli.py", line 245, in get_dag
    raise AirflowException(
airflow.exceptions.AirflowException: Dag 'careerlink_pipeline_1' could not be found; either it does not exist or it failed to parse.
